Traceback (most recent call last):
  File "analyze_medicare_data.py", line 50, in <module>
    print(row['first_name'], row['last_name'])
KeyError: 'first_name'
